<?xml version="1.0"?>
<robot xmlns:xacro="http://www.ros.org/wiki/xacro" name="niryo_ned2_dual">

    <!-- ==================== GLOBAL INCLUDES ==================== -->
    <!-- Import common parameters and constants -->
    <xacro:include filename="$(find niryo_ned_description)/urdf/ned2/niryo_ned2_param.urdf.xacro"/>

    <!-- ==================== DUAL-ARM PROPERTIES ==================== -->
    <!-- Distance from world origin to each arm base (0.350m = 35cm from center, 0.70m total) -->
    <xacro:property name="arm_offset_distance" value="0.350"/>

    <!-- ==================== WORLD LINK ==================== -->
    <!-- Common world frame for both arms -->
    <link name="world"/>

    <!-- ==================== MACRO - ned2_arm_assembly ==================== -->
    <!-- This macro creates a complete arm assembly with 6 joints
         Parameters:
          - prefix: naming prefix (e.g., "arm_1_", "arm_2_")
          - x_offset: X position relative to world (e.g., -0.350, 0.350)
          - yaw_rotation: rotation around Z-axis (e.g., 0, PI)
    -->
    <xacro:macro name="ned2_arm_assembly" params="prefix x_offset yaw_rotation">

        <!-- ========== WORLD TO ARM BASE JOINT ========== -->
        <!-- Fixed joint positioning this arm relative to world origin -->
        <joint name="${prefix}joint_world" type="fixed">
            <parent link="world"/>
            <child link="${prefix}base_link"/>
            <origin xyz="${x_offset} 0 0" rpy="0 0 ${yaw_rotation}"/>
        </joint>

        <!-- ========== ARM KINEMATICS ========== -->
        <!-- LED Ring Link -->
        <link name="${prefix}led_ring_link"/>

        <!-- Base Link -->
        <link name="${prefix}base_link">
            <inertial>
                <origin xyz="-0.008924 0.0001357 0.052392" rpy="0 0 0"/>
                <mass value="0.71142"/>
                <inertia ixx="0.0017" ixy="0.0" ixz="0.0" iyy="0.0017" iyz="0.0" izz="0.0032"/>
            </inertial>
            <visual>
                <origin xyz="0 0 0" rpy="0 0 0"/>
                <geometry>
                    <mesh filename="package://niryo_ned_description/meshes/ned2/collada/base_link.dae"/>
                </geometry>
            </visual>
            <collision>
                <origin xyz="0 0 0" rpy="-${PI/2} 0 0"/>
                <geometry>
                    <mesh filename="package://niryo_ned_description/meshes/ned2/stl/base_link.stl"/>
                </geometry>
            </collision>
        </link>

        <!-- Shoulder Link -->
        <link name="${prefix}shoulder_link">
            <inertial>
                <origin xyz="-0.031951 0.0080419 0.030675" rpy="0 0 0"/>
                <mass value="0.35056"/>
                <inertia ixx="0.00023875" ixy="2.3853E-08" ixz="2.0596E-06" iyy="0.00032638" iyz="-8.9319E-07"
                         izz="0.00030089"/>
            </inertial>
            <visual>
                <origin xyz="0 0 0" rpy="0 0 ${-PI/2}"/>
                <geometry>
                    <mesh filename="package://niryo_ned_description/meshes/ned2/collada/shoulder_link.dae"/>
                </geometry>
            </visual>
            <collision>
                <origin xyz="0 0 0" rpy="0 0 ${-PI/2}"/>
                <geometry>
                    <mesh filename="package://niryo_ned_description/meshes/ned2/stl/shoulder_link.stl"/>
                </geometry>
            </collision>
        </link>

        <!-- Arm Link -->
        <link name="${prefix}arm_link">
            <inertial>
                <origin xyz="-0.00096976 0.086432 0.0038832" rpy="0 ${PI} 0"/>
                <mass value="1.0838"/>
                <inertia ixx="0.008194" ixy="0.00015602" ixz="-3.434E-06" iyy="0.0011945" iyz="-0.00031298" izz="0.007915"/>
            </inertial>
            <visual>
                <origin xyz="0 0 0" rpy="0 ${PI} 0"/>
                <geometry>
                    <mesh filename="package://niryo_ned_description/meshes/ned2/collada/arm_link.dae"/>
                </geometry>
            </visual>
            <collision>
                <origin xyz="0 0 0" rpy="0 ${PI} 0"/>
                <geometry>
                    <mesh filename="package://niryo_ned_description/meshes/ned2/stl/arm_link.stl"/>
                </geometry>
            </collision>
        </link>

        <!-- Elbow Link -->
        <link name="${prefix}elbow_link">
            <inertial>
                <origin xyz="-0.019703 0.037336 -1.7431E-09" rpy="0 ${PI} 0"/>
                <mass value="0.22126"/>
                <inertia ixx="0.00011754" ixy="-1.2314E-05" ixz="-6.2064E-11" iyy="0.00020851" iyz="9.2393E-11"
                         izz="0.00022753"/>
            </inertial>
            <visual>
                <origin xyz="0 0 0" rpy="0 ${PI} ${-PI/2}"/>
                <geometry>
                    <mesh filename="package://niryo_ned_description/meshes/ned2/collada/elbow_link.dae"/>
                </geometry>
            </visual>
            <collision>
                <origin xyz="0 0 0" rpy="0 ${PI} ${-PI/2}"/>
                <geometry>
                    <mesh filename="package://niryo_ned_description/meshes/ned2/stl/elbow_link.stl"/>
                </geometry>
            </collision>
        </link>

        <!-- Forearm Link -->
        <link name="${prefix}forearm_link">
            <inertial>
                <origin xyz="-0.0049532 7.8351E-06 0.08106" rpy="0 0 0"/>
                <mass value="0.35686"/>
                <inertia ixx="0.0013664" ixy="-9.6367E-08" ixz="0.00013594" iyy="0.0014781" iyz="-1.4596E-07"
                         izz="0.00023715"/>
            </inertial>
            <visual>
                <origin xyz="0 0 0" rpy="0 0 ${-PI/2}"/>
                <geometry>
                    <mesh filename="package://niryo_ned_description/meshes/ned2/collada/forearm_link.dae"/>
                </geometry>
            </visual>
            <collision>
                <origin xyz="0 0 0" rpy="0 0 ${-PI/2}"/>
                <geometry>
                    <mesh filename="package://niryo_ned_description/meshes/ned2/stl/forearm_link.stl"/>
                </geometry>
            </collision>
        </link>

        <!-- Wrist Link -->
        <link name="${prefix}wrist_link">
            <inertial>
                <origin xyz="-0.019666 0.037312 0.0" rpy="0 0 0"/>
                <mass value="0.22126"/>
                <inertia ixx="0.0015" ixy="0.0" ixz="0.0" iyy="0.0015" iyz="0.0" izz="0.0015"/>
            </inertial>
            <visual>
                <origin xyz="0 0 0" rpy="0 0 ${-PI/2}"/>
                <geometry>
                    <mesh filename="package://niryo_ned_description/meshes/ned2/collada/wrist_link.dae"/>
                </geometry>
            </visual>
            <collision>
                <origin xyz="0 0 0" rpy="0 0 ${-PI/2}"/>
                <geometry>
                    <mesh filename="package://niryo_ned_description/meshes/ned2/stl/wrist_link.stl"/>
                </geometry>
            </collision>
        </link>

        <!-- Hand Link -->
        <link name="${prefix}hand_link">
            <inertial>
                <origin xyz="0 0 0.009" rpy="0 0 0"/>
                <mass value="0.0070027"/>
                <inertia ixx="0.0015" ixy="0.0" ixz="0.0" iyy="0.0015" iyz="0.0" izz="0.0015"/>
            </inertial>
            <visual>
                <origin xyz="0 0 0" rpy="0 0 ${-PI/2}"/>
                <geometry>
                    <mesh filename="package://niryo_ned_description/meshes/ned2/collada/hand_link.dae"/>
                </geometry>
            </visual>
            <collision>
                <origin xyz="0 0 0" rpy="0 0 ${-PI/2}"/>
                <geometry>
                    <mesh filename="package://niryo_ned_description/meshes/ned2/stl/hand_link.stl"/>
                </geometry>
            </collision>
        </link>

        <!-- Tool Link (End Effector) -->
        <link name="${prefix}tool_link"/>

        <!-- ========== ARM JOINTS ========== -->

        <!-- Joint 1 - Shoulder Rotation -->
        <joint name="${prefix}joint_1" type="revolute">
            <origin xyz="0 0 0.1013" rpy="0 0 0"/>
            <parent link="${prefix}base_link"/>
            <child link="${prefix}shoulder_link"/>
            <axis xyz="0 0 1"/>
            <limit effort="10.0" velocity="10.0" lower="${(limit_low_shoulder_rotation + safety_pos_margin) * deg_to_rad}"
                   upper="${(limit_up_shoulder_rotation - safety_pos_margin) * deg_to_rad}"/>
        </joint>

        <!-- Joint 2 - Arm Rotation -->
        <joint name="${prefix}joint_2" type="revolute">
            <origin xyz="0 0 0.065" rpy="${PI/2} 0 0"/>
            <parent link="${prefix}shoulder_link"/>
            <child link="${prefix}arm_link"/>
            <axis xyz="0 0 1"/>
            <limit effort="10.0" velocity="8.0" lower="${(limit_low_arm_rotation + safety_pos_margin) * deg_to_rad}"
                   upper="${(limit_up_arm_rotation - safety_pos_margin) * deg_to_rad}"/>
        </joint>

        <!-- Joint 3 - Elbow Rotation -->
        <joint name="${prefix}joint_3" type="revolute">
            <origin xyz="0.012 0.221 0" rpy="0 0 ${PI/2}"/>
            <parent link="${prefix}arm_link"/>
            <child link="${prefix}elbow_link"/>
            <axis xyz="0 0 1"/>
            <limit effort="7.0" velocity="8.0" lower="${(limit_low_elbow_rotation + safety_pos_margin) * deg_to_rad}"
                   upper="${(limit_up_elbow_rotation - safety_pos_margin) * deg_to_rad}"/>
        </joint>

        <!-- Joint 4 - Forearm Rotation -->
        <joint name="${prefix}joint_4" type="revolute">
            <origin xyz="0.0325 -0.065 0" rpy="${PI/2} 0 0"/>
            <parent link="${prefix}elbow_link"/>
            <child link="${prefix}forearm_link"/>
            <axis xyz="0 0 1"/>
            <limit effort="7.0" velocity="2.0" lower="${(limit_low_forearm_rotation + safety_pos_margin) * deg_to_rad}"
                   upper="${(limit_up_forearm_rotation - safety_pos_margin) * deg_to_rad}"/>
        </joint>

        <!-- Joint 5 - Wrist Rotation -->
        <joint name="${prefix}joint_5" type="revolute">
            <origin xyz="0 0 0.17" rpy="${-PI/2} 0 0"/>
            <parent link="${prefix}forearm_link"/>
            <child link="${prefix}wrist_link"/>
            <axis xyz="0 0 1"/>
            <limit effort="6.0" velocity="2.0" lower="${(limit_low_wrist_rotation + safety_pos_margin) * deg_to_rad}"
                   upper="${(limit_up_wrist_rotation - safety_pos_margin) * deg_to_rad}"/>
        </joint>

        <!-- Joint 6 - Hand Rotation -->
        <joint name="${prefix}joint_6" type="revolute">
            <origin xyz="0.00925 -0.0197 0" rpy="${PI/2} 0 0"/>
            <parent link="${prefix}wrist_link"/>
            <child link="${prefix}hand_link"/>
            <axis xyz="0 0 1"/>
            <limit effort="5.0" velocity="2.0" lower="${(limit_low_hand_rotation + safety_pos_margin) * deg_to_rad}"
                   upper="${(limit_up_hand_rotation - safety_pos_margin) * deg_to_rad}"/>
        </joint>

        <!-- Hand to Tool Link -->
        <joint name="${prefix}hand_tool_joint" type="fixed">
            <parent link="${prefix}hand_link"/>
            <child link="${prefix}tool_link"/>
            <origin xyz="0 0 ${distance_hand_tool}" rpy="${PI} -${PI/2} 0"/>
        </joint>

        <!-- LED Ring Joint -->
        <joint name="${prefix}joint_led_ring" type="fixed">
            <parent link="world"/>
            <child link="${prefix}led_ring_link"/>
            <origin xyz="${x_offset} 0 0.0923" rpy="0 0 ${yaw_rotation}"/>
        </joint>

    </xacro:macro>

    <!-- ==================== INSTANTIATE BOTH ARMS ==================== -->
    <!-- Arm 1 - positioned at x=-0.125m, facing +X direction (yaw=0) -->
    <xacro:ned2_arm_assembly prefix="arm_1_" x_offset="${-arm_offset_distance}" yaw_rotation="0"/>

    <!-- Arm 2 - positioned at x=+0.125m, facing -X direction (yaw=PI, 180 degrees) -->
    <xacro:ned2_arm_assembly prefix="arm_2_" x_offset="${arm_offset_distance}" yaw_rotation="${PI}"/>

</robot>
